Exception in thread Thread-1:
Traceback (most recent call last):
  File "/Users/ioaquine/.pyenv/versions/3.9.10/lib/python3.9/threading.py", line 973, in _bootstrap_inner
Exception in thread Thread-2:
Traceback (most recent call last):
  File "/Users/ioaquine/.pyenv/versions/3.9.10/lib/python3.9/threading.py", line 973, in _bootstrap_inner
Exception in thread Thread-3:
Traceback (most recent call last):
Exception in thread Thread-4:
Exception in thread Thread-5:
    self.run()
  File "/Users/ioaquine/.pyenv/versions/3.9.10/lib/python3.9/threading.py", line 910, in run
    self.run()
  File "/Users/ioaquine/.pyenv/versions/3.9.10/lib/python3.9/threading.py", line 910, in run
  File "/Users/ioaquine/.pyenv/versions/3.9.10/lib/python3.9/threading.py", line 973, in _bootstrap_inner
Exception in thread Thread-7:
Traceback (most recent call last):
  File "/Users/ioaquine/.pyenv/versions/3.9.10/lib/python3.9/threading.py", line 973, in _bootstrap_inner
    self._target(*self._args, **self._kwargs)
  File "/Users/ioaquine/Downloads/copper/etl/funding-rates.py", line 9, in snapshot_funding_rates
    db = sqlite3.connect('../dev.db')
sqlite3.OperationalError: unable to open database file
Exception in thread Thread-6:
Traceback (most recent call last):
  File "/Users/ioaquine/.pyenv/versions/3.9.10/lib/python3.9/threading.py", line 973, in _bootstrap_inner
    self.run()
  File "/Users/ioaquine/.pyenv/versions/3.9.10/lib/python3.9/threading.py", line 910, in run
    self._target(*self._args, **self._kwargs)
  File "/Users/ioaquine/Downloads/copper/etl/funding-rates.py", line 9, in snapshot_funding_rates
    db = sqlite3.connect('../dev.db')
sqlite3.OperationalError: unable to open database file
Traceback (most recent call last):
  File "/Users/ioaquine/.pyenv/versions/3.9.10/lib/python3.9/threading.py", line 973, in _bootstrap_inner
    self.run()
  File "/Users/ioaquine/.pyenv/versions/3.9.10/lib/python3.9/threading.py", line 910, in run
    self._target(*self._args, **self._kwargs)
  File "/Users/ioaquine/Downloads/copper/etl/funding-rates.py", line 9, in snapshot_funding_rates
    db = sqlite3.connect('../dev.db')
sqlite3.OperationalError: unable to open database file
Exception in thread Thread-10:
Traceback (most recent call last):
  File "/Users/ioaquine/.pyenv/versions/3.9.10/lib/python3.9/threading.py", line 973, in _bootstrap_inner
    self.run()
  File "/Users/ioaquine/.pyenv/versions/3.9.10/lib/python3.9/threading.py", line 910, in run
    self._target(*self._args, **self._kwargs)
  File "/Users/ioaquine/Downloads/copper/etl/funding-rates.py", line 9, in snapshot_funding_rates
    db = sqlite3.connect('../dev.db')
sqlite3.OperationalError: unable to open database file
Exception in thread Thread-8:
Traceback (most recent call last):
  File "/Users/ioaquine/.pyenv/versions/3.9.10/lib/python3.9/threading.py", line 973, in _bootstrap_inner
    self.run()
  File "/Users/ioaquine/.pyenv/versions/3.9.10/lib/python3.9/threading.py", line 910, in run
    self._target(*self._args, **self._kwargs)
  File "/Users/ioaquine/Downloads/copper/etl/funding-rates.py", line 9, in snapshot_funding_rates
    db = sqlite3.connect('../dev.db')
sqlite3.OperationalError: unable to open database file
Traceback (most recent call last):
  File "/Users/ioaquine/.pyenv/versions/3.9.10/lib/python3.9/threading.py", line 973, in _bootstrap_inner
    self.run()
  File "/Users/ioaquine/.pyenv/versions/3.9.10/lib/python3.9/threading.py", line 910, in run
    self._target(*self._args, **self._kwargs)
  File "/Users/ioaquine/Downloads/copper/etl/funding-rates.py", line 9, in snapshot_funding_rates
    db = sqlite3.connect('../dev.db')
sqlite3.OperationalError: unable to open database file
    self.run()
  File "/Users/ioaquine/.pyenv/versions/3.9.10/lib/python3.9/threading.py", line 910, in run
    self._target(*self._args, **self._kwargs)
  File "/Users/ioaquine/Downloads/copper/etl/funding-rates.py", line 9, in snapshot_funding_rates
    db = sqlite3.connect('../dev.db')
sqlite3.OperationalError: unable to open database file
Exception in thread Thread-9:
Traceback (most recent call last):
  File "/Users/ioaquine/.pyenv/versions/3.9.10/lib/python3.9/threading.py", line 973, in _bootstrap_inner
    self._target(*self._args, **self._kwargs)
  File "/Users/ioaquine/Downloads/copper/etl/funding-rates.py", line 9, in snapshot_funding_rates
    db = sqlite3.connect('../dev.db')
sqlite3.OperationalError: unable to open database file
    self.run()
  File "/Users/ioaquine/.pyenv/versions/3.9.10/lib/python3.9/threading.py", line 910, in run
    self._target(*self._args, **self._kwargs)
  File "/Users/ioaquine/Downloads/copper/etl/funding-rates.py", line 9, in snapshot_funding_rates
    db = sqlite3.connect('../dev.db')
sqlite3.OperationalError: unable to open database file
Exception in thread Thread-11:
Traceback (most recent call last):
  File "/Users/ioaquine/.pyenv/versions/3.9.10/lib/python3.9/threading.py", line 973, in _bootstrap_inner
    self.run()
  File "/Users/ioaquine/.pyenv/versions/3.9.10/lib/python3.9/threading.py", line 910, in run
    self._target(*self._args, **self._kwargs)
  File "/Users/ioaquine/Downloads/copper/etl/funding-rates.py", line 9, in snapshot_funding_rates
Exception in thread Thread-12:
Traceback (most recent call last):
  File "/Users/ioaquine/.pyenv/versions/3.9.10/lib/python3.9/threading.py", line 973, in _bootstrap_inner
    self.run()
  File "/Users/ioaquine/.pyenv/versions/3.9.10/lib/python3.9/threading.py", line 910, in run
    db = sqlite3.connect('../dev.db')
sqlite3.OperationalError: unable to open database file
    self.run()
  File "/Users/ioaquine/.pyenv/versions/3.9.10/lib/python3.9/threading.py", line 910, in run
    self._target(*self._args, **self._kwargs)
  File "/Users/ioaquine/Downloads/copper/etl/funding-rates.py", line 9, in snapshot_funding_rates
    self._target(*self._args, **self._kwargs)
    db = sqlite3.connect('../dev.db')
  File "/Users/ioaquine/Downloads/copper/etl/funding-rates.py", line 9, in snapshot_funding_rates
sqlite3.OperationalError: unable to open database file
    db = sqlite3.connect('../dev.db')
sqlite3.OperationalError: unable to open database file
Exception in thread Thread-2:
Traceback (most recent call last):
  File "/Users/ioaquine/.pyenv/versions/3.9.10/lib/python3.9/threading.py", line 973, in _bootstrap_inner
Exception in thread Thread-1:
Exception in thread Thread-3:
Traceback (most recent call last):
  File "/Users/ioaquine/.pyenv/versions/3.9.10/lib/python3.9/threading.py", line 973, in _bootstrap_inner
Traceback (most recent call last):
Exception in thread Thread-4:
Traceback (most recent call last):
  File "/Users/ioaquine/.pyenv/versions/3.9.10/lib/python3.9/threading.py", line 973, in _bootstrap_inner
Exception in thread Thread-5:
Traceback (most recent call last):
  File "/Users/ioaquine/.pyenv/versions/3.9.10/lib/python3.9/threading.py", line 973, in _bootstrap_inner
  File "/Users/ioaquine/.pyenv/versions/3.9.10/lib/python3.9/threading.py", line 973, in _bootstrap_inner
    self.run()
    self.run()
  File "/Users/ioaquine/.pyenv/versions/3.9.10/lib/python3.9/threading.py", line 910, in run
    self.run()
  File "/Users/ioaquine/.pyenv/versions/3.9.10/lib/python3.9/threading.py", line 910, in run
Exception in thread Thread-7:
  File "/Users/ioaquine/.pyenv/versions/3.9.10/lib/python3.9/threading.py", line 910, in run
    self.run()
Exception in thread Thread-9:
Traceback (most recent call last):
  File "/Users/ioaquine/.pyenv/versions/3.9.10/lib/python3.9/threading.py", line 973, in _bootstrap_inner
    self.run()
  File "/Users/ioaquine/.pyenv/versions/3.9.10/lib/python3.9/threading.py", line 910, in run
Traceback (most recent call last):
  File "/Users/ioaquine/.pyenv/versions/3.9.10/lib/python3.9/threading.py", line 973, in _bootstrap_inner
    self.run()
  File "/Users/ioaquine/.pyenv/versions/3.9.10/lib/python3.9/threading.py", line 910, in run
    self._target(*self._args, **self._kwargs)
  File "/Users/ioaquine/Downloads/copper/etl/funding-rates.py", line 9, in snapshot_funding_rates
Exception in thread Thread-10:
Traceback (most recent call last):
  File "/Users/ioaquine/.pyenv/versions/3.9.10/lib/python3.9/threading.py", line 973, in _bootstrap_inner
    self._target(*self._args, **self._kwargs)
Exception in thread Thread-6:
Exception in thread Thread-11:
Traceback (most recent call last):
  File "/Users/ioaquine/.pyenv/versions/3.9.10/lib/python3.9/threading.py", line 973, in _bootstrap_inner
Exception in thread Thread-12:
Traceback (most recent call last):
    self.run()
    self._target(*self._args, **self._kwargs)
  File "/Users/ioaquine/Downloads/copper/etl/funding-rates.py", line 9, in snapshot_funding_rates
    self._target(*self._args, **self._kwargs)
  File "/Users/ioaquine/Downloads/copper/etl/funding-rates.py", line 9, in snapshot_funding_rates
    db = sqlite3.connect('../dev.db')
Traceback (most recent call last):
    db = sqlite3.connect('../dev.db')
    self._target(*self._args, **self._kwargs)
    self.run()
  File "/Users/ioaquine/.pyenv/versions/3.9.10/lib/python3.9/threading.py", line 910, in run
    db = sqlite3.connect('../dev.db')
sqlite3.OperationalError: unable to open database file
  File "/Users/ioaquine/.pyenv/versions/3.9.10/lib/python3.9/threading.py", line 910, in run
  File "/Users/ioaquine/.pyenv/versions/3.9.10/lib/python3.9/threading.py", line 973, in _bootstrap_inner
  File "/Users/ioaquine/.pyenv/versions/3.9.10/lib/python3.9/threading.py", line 910, in run
sqlite3.OperationalError: unable to open database file
Exception in thread Thread-8:
  File "/Users/ioaquine/Downloads/copper/etl/funding-rates.py", line 9, in snapshot_funding_rates
    self._target(*self._args, **self._kwargs)
  File "/Users/ioaquine/Downloads/copper/etl/funding-rates.py", line 9, in snapshot_funding_rates
  File "/Users/ioaquine/Downloads/copper/etl/funding-rates.py", line 9, in snapshot_funding_rates
Traceback (most recent call last):
  File "/Users/ioaquine/.pyenv/versions/3.9.10/lib/python3.9/threading.py", line 973, in _bootstrap_inner
    self._target(*self._args, **self._kwargs)
sqlite3.OperationalError: unable to open database file
  File "/Users/ioaquine/.pyenv/versions/3.9.10/lib/python3.9/threading.py", line 973, in _bootstrap_inner
    db = sqlite3.connect('../dev.db')
sqlite3.OperationalError: unable to open database file
    db = sqlite3.connect('../dev.db')
    self._target(*self._args, **self._kwargs)
    db = sqlite3.connect('../dev.db')
  File "/Users/ioaquine/Downloads/copper/etl/funding-rates.py", line 9, in snapshot_funding_rates
    self.run()
  File "/Users/ioaquine/.pyenv/versions/3.9.10/lib/python3.9/threading.py", line 910, in run
sqlite3.OperationalError: unable to open database file
    self.run()
    self.run()
    db = sqlite3.connect('../dev.db')
sqlite3.OperationalError: unable to open database file
sqlite3.OperationalError: unable to open database file
  File "/Users/ioaquine/.pyenv/versions/3.9.10/lib/python3.9/threading.py", line 910, in run
  File "/Users/ioaquine/Downloads/copper/etl/funding-rates.py", line 9, in snapshot_funding_rates
    self._target(*self._args, **self._kwargs)
  File "/Users/ioaquine/Downloads/copper/etl/funding-rates.py", line 9, in snapshot_funding_rates
    db = sqlite3.connect('../dev.db')
sqlite3.OperationalError: unable to open database file
    db = sqlite3.connect('../dev.db')
sqlite3.OperationalError: unable to open database file
    self._target(*self._args, **self._kwargs)
  File "/Users/ioaquine/Downloads/copper/etl/funding-rates.py", line 9, in snapshot_funding_rates
    db = sqlite3.connect('../dev.db')
sqlite3.OperationalError: unable to open database file
    self.run()
  File "/Users/ioaquine/.pyenv/versions/3.9.10/lib/python3.9/threading.py", line 910, in run
  File "/Users/ioaquine/.pyenv/versions/3.9.10/lib/python3.9/threading.py", line 910, in run
    self._target(*self._args, **self._kwargs)
  File "/Users/ioaquine/Downloads/copper/etl/funding-rates.py", line 9, in snapshot_funding_rates
    db = sqlite3.connect('../dev.db')
sqlite3.OperationalError: unable to open database file
    self._target(*self._args, **self._kwargs)
  File "/Users/ioaquine/Downloads/copper/etl/funding-rates.py", line 9, in snapshot_funding_rates
    db = sqlite3.connect('../dev.db')
sqlite3.OperationalError: unable to open database file
Exception in thread Thread-1:
Exception in thread Thread-2:
Traceback (most recent call last):
  File "/Users/ioaquine/.pyenv/versions/3.9.10/lib/python3.9/threading.py", line 973, in _bootstrap_inner
Exception in thread Thread-6:
Exception in thread Thread-4:
Traceback (most recent call last):
  File "/Users/ioaquine/.pyenv/versions/3.9.10/lib/python3.9/threading.py", line 973, in _bootstrap_inner
Exception in thread Thread-5:
Exception in thread Thread-7:
Traceback (most recent call last):
  File "/Users/ioaquine/.pyenv/versions/3.9.10/lib/python3.9/threading.py", line 973, in _bootstrap_inner
Exception in thread Thread-8:
Exception in thread Thread-3:
Traceback (most recent call last):
  File "/Users/ioaquine/.pyenv/versions/3.9.10/lib/python3.9/threading.py", line 973, in _bootstrap_inner
Exception in thread Thread-9:
Traceback (most recent call last):
  File "/Users/ioaquine/.pyenv/versions/3.9.10/lib/python3.9/threading.py", line 973, in _bootstrap_inner
    self.run()
    self.run()
  File "/Users/ioaquine/.pyenv/versions/3.9.10/lib/python3.9/threading.py", line 910, in run
    self.run()
  File "/Users/ioaquine/.pyenv/versions/3.9.10/lib/python3.9/threading.py", line 910, in run
Traceback (most recent call last):
  File "/Users/ioaquine/.pyenv/versions/3.9.10/lib/python3.9/threading.py", line 910, in run
    self.run()
  File "/Users/ioaquine/.pyenv/versions/3.9.10/lib/python3.9/threading.py", line 910, in run
Exception in thread Thread-11:
    self._target(*self._args, **self._kwargs)
Traceback (most recent call last):
  File "/Users/ioaquine/.pyenv/versions/3.9.10/lib/python3.9/threading.py", line 973, in _bootstrap_inner
    self.run()
    self._target(*self._args, **self._kwargs)
Exception in thread Thread-12:
Traceback (most recent call last):
  File "/Users/ioaquine/.pyenv/versions/3.9.10/lib/python3.9/threading.py", line 973, in _bootstrap_inner
Traceback (most recent call last):
  File "/Users/ioaquine/.pyenv/versions/3.9.10/lib/python3.9/threading.py", line 973, in _bootstrap_inner
    self._target(*self._args, **self._kwargs)
Traceback (most recent call last):
  File "/Users/ioaquine/.pyenv/versions/3.9.10/lib/python3.9/threading.py", line 973, in _bootstrap_inner
  File "/Users/ioaquine/Downloads/copper/etl/funding-rates.py", line 9, in snapshot_funding_rates
  File "/Users/ioaquine/.pyenv/versions/3.9.10/lib/python3.9/threading.py", line 910, in run
  File "/Users/ioaquine/Downloads/copper/etl/funding-rates.py", line 9, in snapshot_funding_rates
  File "/Users/ioaquine/Downloads/copper/etl/funding-rates.py", line 9, in snapshot_funding_rates
Exception in thread Thread-10:
Traceback (most recent call last):
    db = sqlite3.connect('../dev.db')
    self.run()
  File "/Users/ioaquine/.pyenv/versions/3.9.10/lib/python3.9/threading.py", line 973, in _bootstrap_inner
    self.run()
    db = sqlite3.connect('../dev.db')
    self._target(*self._args, **self._kwargs)
sqlite3.OperationalError: unable to open database file
  File "/Users/ioaquine/.pyenv/versions/3.9.10/lib/python3.9/threading.py", line 910, in run
  File "/Users/ioaquine/.pyenv/versions/3.9.10/lib/python3.9/threading.py", line 910, in run
sqlite3.OperationalError: unable to open database file
  File "/Users/ioaquine/Downloads/copper/etl/funding-rates.py", line 9, in snapshot_funding_rates
    self._target(*self._args, **self._kwargs)
  File "/Users/ioaquine/.pyenv/versions/3.9.10/lib/python3.9/threading.py", line 973, in _bootstrap_inner
Traceback (most recent call last):
  File "/Users/ioaquine/.pyenv/versions/3.9.10/lib/python3.9/threading.py", line 973, in _bootstrap_inner
    self._target(*self._args, **self._kwargs)
  File "/Users/ioaquine/Downloads/copper/etl/funding-rates.py", line 9, in snapshot_funding_rates
    self.run()
    db = sqlite3.connect('../dev.db')
  File "/Users/ioaquine/Downloads/copper/etl/funding-rates.py", line 9, in snapshot_funding_rates
    db = sqlite3.connect('../dev.db')
  File "/Users/ioaquine/.pyenv/versions/3.9.10/lib/python3.9/threading.py", line 910, in run
    self.run()
  File "/Users/ioaquine/.pyenv/versions/3.9.10/lib/python3.9/threading.py", line 910, in run
    self.run()
  File "/Users/ioaquine/.pyenv/versions/3.9.10/lib/python3.9/threading.py", line 910, in run
    db = sqlite3.connect('../dev.db')
    self.run()
  File "/Users/ioaquine/.pyenv/versions/3.9.10/lib/python3.9/threading.py", line 910, in run
    self._target(*self._args, **self._kwargs)
  File "/Users/ioaquine/Downloads/copper/etl/funding-rates.py", line 9, in snapshot_funding_rates
    self._target(*self._args, **self._kwargs)
sqlite3.OperationalError: unable to open database file
    self.run()
    self._target(*self._args, **self._kwargs)
  File "/Users/ioaquine/Downloads/copper/etl/funding-rates.py", line 9, in snapshot_funding_rates
    db = sqlite3.connect('../dev.db')
sqlite3.OperationalError: unable to open database file
sqlite3.OperationalError: unable to open database file
    self._target(*self._args, **self._kwargs)
    db = sqlite3.connect('../dev.db')
  File "/Users/ioaquine/Downloads/copper/etl/funding-rates.py", line 9, in snapshot_funding_rates
    db = sqlite3.connect('../dev.db')
    self._target(*self._args, **self._kwargs)
  File "/Users/ioaquine/.pyenv/versions/3.9.10/lib/python3.9/threading.py", line 910, in run
    db = sqlite3.connect('../dev.db')
sqlite3.OperationalError: unable to open database file
    self._target(*self._args, **self._kwargs)
  File "/Users/ioaquine/Downloads/copper/etl/funding-rates.py", line 9, in snapshot_funding_rates
    db = sqlite3.connect('../dev.db')
sqlite3.OperationalError: unable to open database file
  File "/Users/ioaquine/Downloads/copper/etl/funding-rates.py", line 9, in snapshot_funding_rates
    db = sqlite3.connect('../dev.db')
sqlite3.OperationalError: unable to open database file
  File "/Users/ioaquine/Downloads/copper/etl/funding-rates.py", line 9, in snapshot_funding_rates
sqlite3.OperationalError: unable to open database file
sqlite3.OperationalError: unable to open database file
sqlite3.OperationalError: unable to open database file
    db = sqlite3.connect('../dev.db')
sqlite3.OperationalError: unable to open database file
Exception in thread Thread-1:
Traceback (most recent call last):
  File "/Users/ioaquine/.pyenv/versions/3.9.10/lib/python3.9/threading.py", line 973, in _bootstrap_inner
    self.run()
  File "/Users/ioaquine/.pyenv/versions/3.9.10/lib/python3.9/threading.py", line 910, in run
    self._target(*self._args, **self._kwargs)
  File "/Users/ioaquine/Downloads/copper/etl/funding-rates.py", line 9, in snapshot_funding_rates
    db = sqlite3.connect('../dev.db')
sqlite3.OperationalError: unable to open database file
Exception in thread Thread-2:
Traceback (most recent call last):
  File "/Users/ioaquine/.pyenv/versions/3.9.10/lib/python3.9/threading.py", line 973, in _bootstrap_inner
    self.run()
  File "/Users/ioaquine/.pyenv/versions/3.9.10/lib/python3.9/threading.py", line 910, in run
    self._target(*self._args, **self._kwargs)
  File "/Users/ioaquine/Downloads/copper/etl/funding-rates.py", line 9, in snapshot_funding_rates
    db = sqlite3.connect('../dev.db')
sqlite3.OperationalError: unable to open database file
Exception in thread Thread-3:
Traceback (most recent call last):
  File "/Users/ioaquine/.pyenv/versions/3.9.10/lib/python3.9/threading.py", line 973, in _bootstrap_inner
    self.run()
  File "/Users/ioaquine/.pyenv/versions/3.9.10/lib/python3.9/threading.py", line 910, in run
    self._target(*self._args, **self._kwargs)
  File "/Users/ioaquine/Downloads/copper/etl/funding-rates.py", line 9, in snapshot_funding_rates
    db = sqlite3.connect('../dev.db')
sqlite3.OperationalError: unable to open database file
Exception in thread Thread-4:
Traceback (most recent call last):
  File "/Users/ioaquine/.pyenv/versions/3.9.10/lib/python3.9/threading.py", line 973, in _bootstrap_inner
    self.run()
  File "/Users/ioaquine/.pyenv/versions/3.9.10/lib/python3.9/threading.py", line 910, in run
    self._target(*self._args, **self._kwargs)
  File "/Users/ioaquine/Downloads/copper/etl/funding-rates.py", line 9, in snapshot_funding_rates
    db = sqlite3.connect('../dev.db')
sqlite3.OperationalError: unable to open database file
Exception in thread Thread-5:
Traceback (most recent call last):
  File "/Users/ioaquine/.pyenv/versions/3.9.10/lib/python3.9/threading.py", line 973, in _bootstrap_inner
    self.run()
  File "/Users/ioaquine/.pyenv/versions/3.9.10/lib/python3.9/threading.py", line 910, in run
    self._target(*self._args, **self._kwargs)
  File "/Users/ioaquine/Downloads/copper/etl/funding-rates.py", line 9, in snapshot_funding_rates
    db = sqlite3.connect('../dev.db')
sqlite3.OperationalError: unable to open database file
Exception in thread Thread-6:
Traceback (most recent call last):
  File "/Users/ioaquine/.pyenv/versions/3.9.10/lib/python3.9/threading.py", line 973, in _bootstrap_inner
    self.run()
  File "/Users/ioaquine/.pyenv/versions/3.9.10/lib/python3.9/threading.py", line 910, in run
    self._target(*self._args, **self._kwargs)
  File "/Users/ioaquine/Downloads/copper/etl/funding-rates.py", line 9, in snapshot_funding_rates
    db = sqlite3.connect('../dev.db')
sqlite3.OperationalError: unable to open database file
Exception in thread Thread-7:
Traceback (most recent call last):
  File "/Users/ioaquine/.pyenv/versions/3.9.10/lib/python3.9/threading.py", line 973, in _bootstrap_inner
    self.run()
  File "/Users/ioaquine/.pyenv/versions/3.9.10/lib/python3.9/threading.py", line 910, in run
    self._target(*self._args, **self._kwargs)
  File "/Users/ioaquine/Downloads/copper/etl/funding-rates.py", line 9, in snapshot_funding_rates
    db = sqlite3.connect('../dev.db')
sqlite3.OperationalError: unable to open database file
Exception in thread Thread-8:
Traceback (most recent call last):
  File "/Users/ioaquine/.pyenv/versions/3.9.10/lib/python3.9/threading.py", line 973, in _bootstrap_inner
    self.run()
  File "/Users/ioaquine/.pyenv/versions/3.9.10/lib/python3.9/threading.py", line 910, in run
    self._target(*self._args, **self._kwargs)
  File "/Users/ioaquine/Downloads/copper/etl/funding-rates.py", line 9, in snapshot_funding_rates
    db = sqlite3.connect('../dev.db')
sqlite3.OperationalError: unable to open database file
Exception in thread Thread-9:
Traceback (most recent call last):
  File "/Users/ioaquine/.pyenv/versions/3.9.10/lib/python3.9/threading.py", line 973, in _bootstrap_inner
    self.run()
  File "/Users/ioaquine/.pyenv/versions/3.9.10/lib/python3.9/threading.py", line 910, in run
    self._target(*self._args, **self._kwargs)
  File "/Users/ioaquine/Downloads/copper/etl/funding-rates.py", line 9, in snapshot_funding_rates
    db = sqlite3.connect('../dev.db')
sqlite3.OperationalError: unable to open database file
Exception in thread Thread-10:
Traceback (most recent call last):
  File "/Users/ioaquine/.pyenv/versions/3.9.10/lib/python3.9/threading.py", line 973, in _bootstrap_inner
    self.run()
  File "/Users/ioaquine/.pyenv/versions/3.9.10/lib/python3.9/threading.py", line 910, in run
    self._target(*self._args, **self._kwargs)
  File "/Users/ioaquine/Downloads/copper/etl/funding-rates.py", line 9, in snapshot_funding_rates
    db = sqlite3.connect('../dev.db')
sqlite3.OperationalError: unable to open database file
Exception in thread Thread-11:
Traceback (most recent call last):
  File "/Users/ioaquine/.pyenv/versions/3.9.10/lib/python3.9/threading.py", line 973, in _bootstrap_inner
    self.run()
  File "/Users/ioaquine/.pyenv/versions/3.9.10/lib/python3.9/threading.py", line 910, in run
    self._target(*self._args, **self._kwargs)
  File "/Users/ioaquine/Downloads/copper/etl/funding-rates.py", line 9, in snapshot_funding_rates
    db = sqlite3.connect('../dev.db')
sqlite3.OperationalError: unable to open database file
Exception in thread Thread-12:
Traceback (most recent call last):
  File "/Users/ioaquine/.pyenv/versions/3.9.10/lib/python3.9/threading.py", line 973, in _bootstrap_inner
    self.run()
  File "/Users/ioaquine/.pyenv/versions/3.9.10/lib/python3.9/threading.py", line 910, in run
    self._target(*self._args, **self._kwargs)
  File "/Users/ioaquine/Downloads/copper/etl/funding-rates.py", line 9, in snapshot_funding_rates
    db = sqlite3.connect('../dev.db')
sqlite3.OperationalError: unable to open database file
Exception in thread Thread-1:
Traceback (most recent call last):
  File "/Users/ioaquine/.pyenv/versions/3.9.10/lib/python3.9/threading.py", line 973, in _bootstrap_inner
    self.run()
  File "/Users/ioaquine/.pyenv/versions/3.9.10/lib/python3.9/threading.py", line 910, in run
    self._target(*self._args, **self._kwargs)
  File "/Users/ioaquine/Downloads/copper/etl/funding-rates.py", line 9, in snapshot_funding_rates
    db = sqlite3.connect('../dev.db')
sqlite3.OperationalError: unable to open database file
Exception in thread Thread-4:
Traceback (most recent call last):
  File "/Users/ioaquine/.pyenv/versions/3.9.10/lib/python3.9/threading.py", line 973, in _bootstrap_inner
    self.run()
Exception in thread Thread-3:
Traceback (most recent call last):
  File "/Users/ioaquine/.pyenv/versions/3.9.10/lib/python3.9/threading.py", line 973, in _bootstrap_inner
  File "/Users/ioaquine/.pyenv/versions/3.9.10/lib/python3.9/threading.py", line 910, in run
Exception in thread Thread-5:
Traceback (most recent call last):
  File "/Users/ioaquine/.pyenv/versions/3.9.10/lib/python3.9/threading.py", line 973, in _bootstrap_inner
    self.run()
  File "/Users/ioaquine/.pyenv/versions/3.9.10/lib/python3.9/threading.py", line 910, in run
    self._target(*self._args, **self._kwargs)
  File "/Users/ioaquine/Downloads/copper/etl/funding-rates.py", line 9, in snapshot_funding_rates
    db = sqlite3.connect('../dev.db')
sqlite3.OperationalError: unable to open database file
Exception in thread Thread-2:
Traceback (most recent call last):
  File "/Users/ioaquine/.pyenv/versions/3.9.10/lib/python3.9/threading.py", line 973, in _bootstrap_inner
    self.run()
  File "/Users/ioaquine/.pyenv/versions/3.9.10/lib/python3.9/threading.py", line 910, in run
    self._target(*self._args, **self._kwargs)
  File "/Users/ioaquine/Downloads/copper/etl/funding-rates.py", line 9, in snapshot_funding_rates
    db = sqlite3.connect('../dev.db')
sqlite3.OperationalError: unable to open database file
Exception in thread Thread-10:
Traceback (most recent call last):
  File "/Users/ioaquine/.pyenv/versions/3.9.10/lib/python3.9/threading.py", line 973, in _bootstrap_inner
Exception in thread Thread-7:
Traceback (most recent call last):
  File "/Users/ioaquine/.pyenv/versions/3.9.10/lib/python3.9/threading.py", line 973, in _bootstrap_inner
Exception in thread Thread-8:
Traceback (most recent call last):
  File "/Users/ioaquine/.pyenv/versions/3.9.10/lib/python3.9/threading.py", line 973, in _bootstrap_inner
    self.run()
  File "/Users/ioaquine/.pyenv/versions/3.9.10/lib/python3.9/threading.py", line 910, in run
    self._target(*self._args, **self._kwargs)
  File "/Users/ioaquine/Downloads/copper/etl/funding-rates.py", line 9, in snapshot_funding_rates
    db = sqlite3.connect('../dev.db')
sqlite3.OperationalError: unable to open database file
Exception in thread Thread-12:
Traceback (most recent call last):
  File "/Users/ioaquine/.pyenv/versions/3.9.10/lib/python3.9/threading.py", line 973, in _bootstrap_inner
    self.run()
  File "/Users/ioaquine/.pyenv/versions/3.9.10/lib/python3.9/threading.py", line 910, in run
    self._target(*self._args, **self._kwargs)
    self._target(*self._args, **self._kwargs)
  File "/Users/ioaquine/Downloads/copper/etl/funding-rates.py", line 9, in snapshot_funding_rates
Exception in thread Thread-9:
Traceback (most recent call last):
  File "/Users/ioaquine/.pyenv/versions/3.9.10/lib/python3.9/threading.py", line 973, in _bootstrap_inner
    self.run()
  File "/Users/ioaquine/.pyenv/versions/3.9.10/lib/python3.9/threading.py", line 910, in run
    self._target(*self._args, **self._kwargs)
  File "/Users/ioaquine/Downloads/copper/etl/funding-rates.py", line 9, in snapshot_funding_rates
    db = sqlite3.connect('../dev.db')
sqlite3.OperationalError: unable to open database file
    self.run()
  File "/Users/ioaquine/.pyenv/versions/3.9.10/lib/python3.9/threading.py", line 910, in run
    self._target(*self._args, **self._kwargs)
  File "/Users/ioaquine/Downloads/copper/etl/funding-rates.py", line 9, in snapshot_funding_rates
    db = sqlite3.connect('../dev.db')
sqlite3.OperationalError: unable to open database file
  File "/Users/ioaquine/Downloads/copper/etl/funding-rates.py", line 9, in snapshot_funding_rates
    db = sqlite3.connect('../dev.db')
sqlite3.OperationalError: unable to open database file
Exception in thread Thread-11:
Traceback (most recent call last):
  File "/Users/ioaquine/.pyenv/versions/3.9.10/lib/python3.9/threading.py", line 973, in _bootstrap_inner
Exception in thread Thread-6:
    self.run()
  File "/Users/ioaquine/.pyenv/versions/3.9.10/lib/python3.9/threading.py", line 910, in run
    self.run()
  File "/Users/ioaquine/.pyenv/versions/3.9.10/lib/python3.9/threading.py", line 910, in run
    db = sqlite3.connect('../dev.db')
    self.run()
  File "/Users/ioaquine/.pyenv/versions/3.9.10/lib/python3.9/threading.py", line 910, in run
sqlite3.OperationalError: unable to open database file
    self._target(*self._args, **self._kwargs)
  File "/Users/ioaquine/Downloads/copper/etl/funding-rates.py", line 9, in snapshot_funding_rates
    db = sqlite3.connect('../dev.db')
sqlite3.OperationalError: unable to open database file
    self._target(*self._args, **self._kwargs)
  File "/Users/ioaquine/Downloads/copper/etl/funding-rates.py", line 9, in snapshot_funding_rates
    db = sqlite3.connect('../dev.db')
sqlite3.OperationalError: unable to open database file
Traceback (most recent call last):
  File "/Users/ioaquine/.pyenv/versions/3.9.10/lib/python3.9/threading.py", line 973, in _bootstrap_inner
    self._target(*self._args, **self._kwargs)
  File "/Users/ioaquine/Downloads/copper/etl/funding-rates.py", line 9, in snapshot_funding_rates
    db = sqlite3.connect('../dev.db')
sqlite3.OperationalError: unable to open database file
    self.run()
  File "/Users/ioaquine/.pyenv/versions/3.9.10/lib/python3.9/threading.py", line 910, in run
    self._target(*self._args, **self._kwargs)
  File "/Users/ioaquine/Downloads/copper/etl/funding-rates.py", line 9, in snapshot_funding_rates
    db = sqlite3.connect('../dev.db')
sqlite3.OperationalError: unable to open database file
